ERROR:root:================================================================================
ERROR:root:Sistema de registro de errores del sistema 2025-07-16 21:37:1752716269
ERROR:root:================================================================================
INFO:sqlalchemy.engine.Engine:SELECT DATABASE()
INFO:sqlalchemy.engine.Engine:[raw sql] {}
INFO:sqlalchemy.engine.Engine:SELECT @@sql_mode
INFO:sqlalchemy.engine.Engine:[raw sql] {}
INFO:sqlalchemy.engine.Engine:SELECT @@lower_case_table_names
INFO:sqlalchemy.engine.Engine:[raw sql] {}
INFO:sqlalchemy.engine.Engine:BEGIN (implicit)
INFO:sqlalchemy.engine.Engine:DESCRIBE `tripleup`.`usuario`
INFO:sqlalchemy.engine.Engine:[raw sql] {}
INFO:sqlalchemy.engine.Engine:DESCRIBE `tripleup`.`confirmation_user`
INFO:sqlalchemy.engine.Engine:[raw sql] {}
INFO:sqlalchemy.engine.Engine:DESCRIBE `tripleup`.`familia_afiliado`
INFO:sqlalchemy.engine.Engine:[raw sql] {}
INFO:sqlalchemy.engine.Engine:DESCRIBE `tripleup`.`bitacora`
INFO:sqlalchemy.engine.Engine:[raw sql] {}
INFO:sqlalchemy.engine.Engine:COMMIT
INFO:sqlalchemy.engine.Engine:BEGIN (implicit)
INFO:sqlalchemy.engine.Engine:SELECT count(*) AS count_1 
FROM (SELECT usuario.id AS usuario_id, usuario.username AS usuario_username, usuario.password AS usuario_password, usuario.estado AS usuario_estado, usuario.confirmado AS usuario_confirmado, usuario.id_nivel AS usuario_id_nivel, usuario.codigo AS usuario_codigo, usuario.created AS usuario_created, usuario.updated AS usuario_updated, usuario.confirmated AS usuario_confirmated 
FROM usuario 
WHERE usuario.id = %(id_1)s) AS anon_1
INFO:sqlalchemy.engine.Engine:[generated in 0.00038s] {'id_1': 1}
INFO:sqlalchemy.engine.Engine:SELECT count(*) AS count_1 
FROM (SELECT familia_afiliado.id AS familia_afiliado_id, familia_afiliado.user_id AS familia_afiliado_user_id, familia_afiliado.codigo_ascendente AS familia_afiliado_codigo_ascendente, familia_afiliado.familiar_id AS familia_afiliado_familiar_id, familia_afiliado.codigo_descendente AS familia_afiliado_codigo_descendente, familia_afiliado.tipo AS familia_afiliado_tipo, familia_afiliado.created AS familia_afiliado_created, familia_afiliado.updated AS familia_afiliado_updated 
FROM familia_afiliado 
WHERE familia_afiliado.user_id = %(user_id_1)s AND familia_afiliado.tipo = %(tipo_1)s) AS anon_1
INFO:sqlalchemy.engine.Engine:[generated in 0.00035s] {'user_id_1': 1, 'tipo_1': 1}
INFO:sqlalchemy.engine.Engine:SELECT id, user_id, nombres, apellidos, sexo, fecha_nac, created, updated, tipo, codigo_ascendente, codigo_descendente, id_ascendente 
FROM view_familiares 
WHERE id_ascendente = %(id_ascendente_1)s AND tipo = %(tipo_1)s
INFO:sqlalchemy.engine.Engine:[generated in 0.00022s] {'id_ascendente_1': 1, 'tipo_1': 1}
ERROR:sqlalchemy.pool.impl.QueuePool:Exception during reset or similar
Traceback (most recent call last):
  File "/home/egonzalez/project/tripleup/venv/lib64/python3.12/site-packages/pymysql/connections.py", line 806, in _write_bytes
    self._sock.sendall(data)
ConnectionResetError: [Errno 104] Connection reset by peer

During handling of the above exception, another exception occurred:

Traceback (most recent call last):
  File "/home/egonzalez/project/tripleup/venv/lib64/python3.12/site-packages/sqlalchemy/pool/base.py", line 987, in _finalize_fairy
    fairy._reset(
  File "/home/egonzalez/project/tripleup/venv/lib64/python3.12/site-packages/sqlalchemy/pool/base.py", line 1433, in _reset
    pool._dialect.do_rollback(self)
  File "/home/egonzalez/project/tripleup/venv/lib64/python3.12/site-packages/sqlalchemy/engine/default.py", line 703, in do_rollback
    dbapi_connection.rollback()
  File "/home/egonzalez/project/tripleup/venv/lib64/python3.12/site-packages/pymysql/connections.py", line 492, in rollback
    self._execute_command(COMMAND.COM_QUERY, "ROLLBACK")
  File "/home/egonzalez/project/tripleup/venv/lib64/python3.12/site-packages/pymysql/connections.py", line 864, in _execute_command
    self._write_bytes(packet)
  File "/home/egonzalez/project/tripleup/venv/lib64/python3.12/site-packages/pymysql/connections.py", line 809, in _write_bytes
    raise err.OperationalError(
pymysql.err.OperationalError: (2006, "MySQL server has gone away (ConnectionResetError(104, 'Connection reset by peer'))")
